Workbook

Sheet RESUMEN_1
D2: FASE1 | F2: FASE2
A3: Row Labels | B3: Sum of ESTIMACION (DIAS) | C3: Sum of ESTIMACION (MESES) | D3: BACK | E3: FRONT | F3: FRONT | G3: BACK
A4: BACK | B4: 93 | C4: 4.65
A5: DASHBOARD | B5: 25.5 | C5: 1.275 | G5: 1.275
A6: GENERAL | B6: 30.5 | C6: 1.525 | D6: 1.525
A7: MOVIL | B7: 25.25 | C7: 1.2625 | D7: 1.2625
A8: VECTORPAI | B8: 11.75 | C8: 0.5875 | D8: 0.5875
A9: FRONT | B9: 69.5 | C9: 3.475
A10: DASHBOARD | B10: 31.5 | C10: 1.575 | F10: 1.575
A11: MOVIL | B11: 32.5 | C11: 1.625 | E11: 1.625
A12: VECTORPAI | B12: 5.5 | C12: 0.275 | E12: 0.28
A13: ARQ | B13: 5.5 | C13: 0.275
A14: GENERAL | B14: 5.5 | C14: 0.275 | E14: 0.28
A15: PRUE | B15: 15 | C15: 0.75
A16: GENERAL | B16: 15 | C16: 0.75 | D16: 0.75 | F16: 0.75
A17: LIB | B17: 11.25 | C17: 0.5625
A18: GENERAL | B18: 11.25 | C18: 0.5625 | D18: 0.5625
A19: Grand Total | B19: 194.25 | C19: 9.7125
D20: =SUM(D6:D19) -> 4.6875 | F20: =SUM(F4:F19) -> 2.325
D21: MAY-SEP 2025 | F21: OCT-NOV 2025
D22: APP | F22: DASHBOARD

Sheet RESUMEN_2
A3: Row Labels | B3: Sum of ESTIMACION (DIAS) | C3: Sum of ESTIMACION (MESES)
A4: DASHBOARD | B4: 57 | C4: 2.85
A5: BACK | B5: 25.5 | C5: 1.275
A6: FRONT | B6: 31.5 | C6: 1.575
A7: GENERAL | B7: 62.25 | C7: 3.1125
A8: BACK | B8: 30.5 | C8: 1.525
A9: ARQ | B9: 5.5 | C9: 0.275
A10: PRUE | B10: 15 | C10: 0.75
A11: LIB | B11: 11.25 | C11: 0.5625
A12: MOVIL | B12: 57.75 | C12: 2.8875
A13: BACK | B13: 25.25 | C13: 1.2625
A14: FRONT | B14: 32.5 | C14: 1.625
A15: VECTORPAI | B15: 17.25 | C15: 0.8625
... A18: Grand Total | B18: 194.25 | C18: 9.7125

Sheet ACTIVIDADES
A1: PLATAFORMA | B1: TIPO | C1: REQ | D1: PERFILES | E1: MODULO | F1: METODO | G1: HEADERS JWT | H1: SERVICIO | I1: DESCRIPCION | J1: FASE2 | K1: ESTIMACION (HRS) | L1: ESTIMACION (DIAS) | M1: ESTIMACION (MESES)
A2: GENERAL | B2: AWS | C2: BACK | I2: Script para dar de alta SuperUsurio para Adminisitrar Adminsitradores | K2: 8 | L2: =K2/8 -> 1 | M2: =L2/20 -> 0.05
A3: GENERAL | B3: AWS | C3: BACK | I3: Script para generar estructuras de tablas nuevas de base de datos y carga inicial de datos y catalogos | K3: 20 | L3: =K3/8 -> 2.5 | M3: =L3/20 -> 0.125
A4: GENERAL | B4: .NET | C4: BACK | I4: Ruteo de peticiones REST a distintas base de datos dependiendo del Origen solicitado | K4: 16 | L4: =K4/8 -> 2 | M4: =L4/20 -> 0.1 | O4: AWS LAMBDA
A5: GENERAL | B5: AWS | C5: BACK | I5: Preparar nuevo PROYECTO para este set de servicios | K5: 8 | L5: =K5/8 -> 1 | M5: =L5/20 -> 0.05
A6: GENERAL | B6: .NET | C6: BACK | I6: Preparar ejemplo de servicio base GET/PUT/POST/DEL, con manejo de sesion JWT, validaciones y bitacora; para replicar en el universo de servicios | K6: 16 | L6: =K6/8 -> 2 | M6: =L6/20 -> 0.1 | O6: AWS LAMBDA
A7: GENERAL | B7: .NET | C7: ARQ | I7: Preparar proceso asincrono para generar archivo JSON de empresa SOLO para la empresa con bandera ACTIVOAPP true (JAVA) | K7: 20 | L7: =K7/8 -> 2.5 | M7: =L7/20 -> 0.125
A8: GENERAL | B8: .NET | C8: BACK | I8: Realizar envio de archivo JSON a bucket S3 AWS de empresas | K8: 20 | L8: =K8/8 -> 2.5 | M8: =L8/20 -> 0.125
A9: GENERAL | B9: AWS | C9: BACK | I9: Prepara CDK cdk-apisvector-pai: apigateway, lambdas, sqs, s3 | K9: 8 | L9: =K9/8 -> 1 | M9: =L9/20 -> 0.05
A10: GENERAL | B10: AWS | C10: BACK | I10: Prepara CDK cdk-apisvector-pai: estructuras de tablas dynamodb, json empresa; estatus proceso sqs, etc | K10: 8 | L10: =K10/8 -> 1 | M10: =L10/20 -> 0.05
A11: GENERAL | B11: AWS | C11: BACK | I11: Prepara CDK cdk-apisvector-pai: apigateway's domain vectorpai.api.vectordev.com.mx | K11: 8 | L11: =K11/8 -> 1 | M11: =L11/20 -> 0.05
A12: GENERAL | B12: AWS | C12: BACK | I12: Prepara CDK cdk-apisvector-pai: CID con workflow de git (Continuous integration deployment) | K12: 16 | L12: =K12/8 -> 2 | M12: =L12/20 -> 0.1
A13: GENERAL | B13: AWS | C13: BACK | I13: Configuracion de correos de codigo de activacion y codigo de confirmacion, templates | K13: 16 | L13: =K13/8 -> 2 | M13: =L13/20 -> 0.1
A14: GENERAL | B14: AWS | C14: BACK | I14: Configuracion de Cognito, user pools | K14: 8 | L14: =K14/8 -> 1 | M14: =L14/20 -> 0.05
A15: GENERAL | B15: AWS | C15: BACK | I15: Tarea para depurar estatus retiros, etc (tareas asincronas con estatus o encolamiento de peticiones) | K15: 16 | L15: =K15/8 -> 2 | M15: =L15/20 -> 0.1
A16: GENERAL | B16: .NET | C16: ARQ | I16: Analisis arquitectura actual por incremento de volumen transaccional | K16: 8 | L16: =K16/8 -> 1 | M16: =L16/20 -> 0.05
A17: GENERAL | B17: .NET | C17: ARQ | I17: Analisis tema: de Manifiesto reactivo en .NET, revisar que el sistema no sea "bloqueante" | K17: 8 | L17: =K17/8 -> 1 | M17: =L17/20 -> 0.05
A18: GENERAL | B18: .NET | C18: ARQ | I18: API MANAGER? Autenticacion AWS/..NET (JWT) | K18: 8 | L18: =K18/8 -> 1 | M18: =L18/20 -> 0.05
... A23: GENERAL | B23: .NET | C23: BACK | I23: Mecanismo de autenticacion desde .NET hacia servicios AWS-lambda para pantallas superusuario (SSO?AWSSDK?) | K23: 16 | L23: =K23/8 -> 2 | M23: =L23/20 -> 0.1
A24: DASHBOARD | B24: LAMBDA/DYNAMODB/COGNITO | C24: BACK | D24: TODOS | E24: REGISTRO | F24: POST | H24: /api/v1/register?type=admin | I24: Servicio para registro de admin: correo, codigoactivacion | K24: 24 | L24: =K24/8 -> 3 | M24: =L24/20 -> 0.15
A25: DASHBOARD | B25: LAMBDA/DYNAMODB/COGNITO | C25: BACK | D25: TODOS | E25: REGISTRO | F25: POST | H25: /api/v1/register/submit?type=admin | I25: Servicio para registro de admin: codigo de confirmacion, pw, cpw | K25: 8 | L25: =K25/8 -> 1 | M25: =L25/20 -> 0.05
A26: DASHBOARD | B26: LAMBDA/COGNITO | C26: BACK | D26: TODOS | E26: LOGIN | F26: POST | H26: /api/v1/login?type=admin | I26: Servicio para login, lambda que se comunica con cognito, obtiene perfil, permisos, menus | K26: 24 | L26: =K26/8 -> 3 | M26: =L26/20 -> 0.15
A27: DASHBOARD | B27: LAMBDA/COGNITO | C27: BACK | D27: TODOS | E27: CERRAR SESION | F27: GET | H27: /api/v1/logout?type=admin | I27: Servicio para cerrar sesion, lambda que se comunica con cognito | K27: 4 | L27: =K27/8 -> 0.5 | M27: =L27/20 -> 0.025
A28: DASHBOARD | B28: LAMBDA/COGNITO | C28: BACK | D28: TODOS | E28: RECUPERACION | F28: POST | H28: /api/v1/recover?type=admin | I28: Servicio para recuperacion: email | K28: 8 | L28: =K28/8 -> 1 | M28: =L28/20 -> 0.05
A29: DASHBOARD | B29: LAMBDA/COGNITO | C29: BACK | D29: TODOS | E29: RECUPERACION | F29: POST | H29: /api/v1/recover/submit?type=admin | I29: Servicio para reuperacion: codigo de confirmacion, pw, cpw | K29: 4 | L29: =K29/8 -> 0.5 | M29: =L29/20 -> 0.025
A30: DASHBOARD | B30: LAMBDA/COGNITO | C30: BACK | D30: TODOS | E30: CAMBIO PW | F30: POST | H30: /api/v1/password/change?type=admin | I30: Servicio para actualizar contraseña | K30: 8 | L30: =K30/8 -> 1 | M30: =L30/20 -> 0.05
A31: DASHBOARD | B31: LAMBDA/DYNAMODB | C31: BACK | D31: TODOS | E31: SELECCIÓN EMPRESA | F31: GET | H31: /api/v1/admin/companies | I31: Servicio para obtener las empresas a las tiene acceso el adminsitrador | K31: 8 | L31: =K31/8 -> 1 | M31: =L31/20 -> 0.05
A32: DASHBOARD | B32: .NET | C32: BACK | D32: TODOS | E32: SELECCIÓN EMPRESA | F32: GET | H32: /api/v1/admin/companies | I32: Servicio para obtener las empresas a las tiene acceso el adminsitrador | K32: 8 | L32: =K32/8 -> 1 | M32: =L32/20 -> 0.05 | N32: Recibe listado de contratos relac
A33: DASHBOARD | B33: LAMBDA/DYNAMODB/.NET | C33: BACK | D33: TODOS | E33: EMPRESA: DASHBOARD | F33: POST | H33: /api/v1/admin/company/dashboard? | I33: Servicio para obtener resumen dashboard de una empresa | J33: 1 | K33: 8 | L33: =K33/8 -> 1 | M33: =L33/20 -> 0.05
A34: DASHBOARD | B34: LAMBDA/DYNAMODB | C34: BACK | D34: TODOS | E34: EMPRESA: PARTICIPANTES | F34: GET | H34: /api/v1/admin/company/persons? | I34: Servicio para consultar participantes de una empresa y sus estatus de activacion; considerar paginacion (10x10) | K34: 16 | L34: =K34/8 -> 2 | M34: =L34/20 -> 0.1
A35: DASHBOARD | B35: .NET | C35: BACK | D35: TODOS | E35: EMPRESA: PARTICIPANTES | F35: GET | H35: /api/v1/admin/company/persons? | I35: Servicio para consultar participantes de una empresa y sus estatus de activacion | K35: 8 | L35: =K35/8 -> 1 | M35: =L35/20 -> 0.05
A36: DASHBOARD | B36: LAMBDA/DYNAMODB | C36: BACK | D36: TODOS | E36: EMPRESA: PARTICIPANTES | F36: POST | H36: /api/v1/admin/company/persons/activate? | I36: Servicio para activar participantes de manera masiva, y lanzar correo de activacion | K36: 24 | L36: =K36/8 -> 3 | M36: =L36/20 -> 0.15
A37: DASHBOARD | B37: LAMBDA/DYNAMODB | C37: BACK | D37: TODOS | E37: EMPRESA: PARTICIPANTES | F37: POST | H37: /api/v1/admin/company/person/activate? | I37: Servicio para activar participantes de manera individual, y lanzar correo de activacion | K37: 8 | L37: =K37/8 -> 1 | M37: =L37/20 -> 0.05
A38: DASHBOARD | B38: LAMBDA/DYNAMODB | C38: BACK | D38: TODOS | E38: EMPRESA: PARTICIPANTES | F38: PUT | H38: /api/v1/admin/company/person? | I38: Servicio para actualizar participante de manera individual: bloqueo, inactivar | K38: 8 | L38: =K38/8 -> 1 | M38: =L38/20 -> 0.05
A39: DASHBOARD | B39: LAMBDA/DYNAMODB | C39: BACK | D39: SISTEMAS/VECTOR | E39: EMPRESA: SERVICIOS | F39: GET | H39: /api/v1/admin/company/services? | I39: Servicio para obtener los servicios de la empresa | J39: 1 | K39: 8 | L39: =K39/8 -> 1 | M39: =L39/20 -> 0.05
A40: DASHBOARD | B40: LAMBDA/DYNAMODB | C40: BACK | D40: SISTEMAS/VECTOR | E40: EMPRESA: SERVICIOS | F40: PUT | H40: /api/v1/admin/company/service? | I40: Servicio para ACTIVAR O DESACTIVAR serviciio de la empresa | J40: 1 | K40: 4 | L40: =K40/8 -> 0.5 | M40: =L40/20 -> 0.025
A41: DASHBOARD | B41: LAMBDA/DYNAMODB | C41: BACK | D41: TODOS | E41: EMPRESA: CONFIGURACION: PARAMETROS | F41: GET | H41: /api/v1/admin/company/config/params? | I41: Servicio para obtener la configuracion de la empresa: aviso, mensaje, bloqueo, etc | K41: 8 | L41: =K41/8 -> 1 | M41: =L41/20 -> 0.05
A42: DASHBOARD | B42: LAMBDA/DYNAMODB | C42: BACK | D42: TODOS | E42: EMPRESA: CONFIGURACION: PARAMETROS | F42: POST | H42: /api/v1/admin/company/config/params? | I42: Servicio para actualizar la configuracion de la empresa: aviso, mensaje, bloqueo, etc | K42: 4 | L42: =K42/8 -> 0.5 | M42: =L42/20 -> 0.025
A43: DASHBOARD | B43: LAMBDA/DYNAMODB | C43: BACK | D43: TODOS | E43: EMPRESA: CONFIGURACION: LOOKANDFEEL | F43: GET | H43: /api/v1/admin/company/config/lookandfeel? | I43: Servicio para obtener la configuracion branding de la empresa | K43: 8 | L43: =K43/8 -> 1 | M43: =L43/20 -> 0.05
A44: DASHBOARD | B44: LAMBDA/DYNAMODB | C44: BACK | D44: TODOS | E44: EMPRESA: CONFIGURACION: LOOKANDFEEL | F44: POST | H44: /api/v1/admin/company/config/lookandfeel? | I44: Servicio para actualizar la configuracion branding de la empresa | K44: 4 | L44: =K44/8 -> 0.5 | M44: =L44/20 -> 0.025
...

Sheet BD_TABLES
A1: NUBE | B1: PREMISE
A5: cental1.PARTIPANTE
A6: CONTRATO | B6: IDEMPRESA | C6: IDPARTICIPANTE | D6: IDTOKENPARTICIPANTE | E6: NOMBRE PART
B7: 3050 | C7: 1234567943 | D7: ABC6451231364
B8: 3051 | C8: 6561231311 | D8: 41C6451231364
B9: 3058 | C9: 9121313133 | D9: DSADAS4D5A13
A11: CATALOGO EMPRESAS
A12: CONTRATO | B12: IDEMPRESA | C12: NOMBRE EMPRESA
A21: USUARIOUNICO (TABLA PUEDE ESTAR EN LA NUBE) | F21: DATOS USUARIO APP
A22: EMAIL | B22: IDUSUARIO_UNICO | C22: CODIGO ACTIVACION | D22: VIGENCIA_CODIGO_ACTIVACION | E22: COGNITO_SUB | F22: OSTYPE | G22: OSVERSION | H22: MODEL | I22: BLOQUEO | J22: MOTIVO BLOQUEO | K22: ESTATUS
A23: macastro@vector.com.mx | B23: 3e01db55-3f84-420f-aca5-031f07579b5b | C23: 912315 | D23: 45801 | E23: D1S2AD3AS1D23A1312323 | F23: ANDROID | G23: 16 | H23: XIAMI | K23: 2 | M23: 1ER REGISTRO
A24: pramirez@vector.com.mx | B24: 31312312-3f84-420f-aca5-031f07579b5b | C24: 81213123 | D24: 45801 | E24: 31JJLAKLDMAPDAS | F24: IOS | G24: 21 | H24: APPLE | K24: 2
A25: hrivera@vector.com.mx | B25: dkasldjlasdkasñlkdña | C25: 999999 | D25: 45801 | E25: djkasjdlkasjkldas | F25: IOS | G25: 21 | H25: APPLE | K25: 2 | L25: **SE GENERA CON SCRIPT
A27: ESTATUS REGISTRO (TABLA PUEDE ESTAR EN LA NUBE) | T27: 0
A28: 0 | B28: INACTIVO
A29: 1 | B29: REGISTRO
A30: 2 | B30: ACTIVO
A31: 9 | B31: BLOQUEO
A33: CAT_GRUPOS
A34: IDGRUPO | B34: ORIGEN | C34: GRUPO
A35: 1 | B35: LEAR | C35: G-LEAR
A36: 2 | B36: CENTRAL1 | C36: G-EMPRESAS VECTOR
A39: REL_GRUPO_CONTRATO
A40: IDGRUPO | B40: CONTRATO | C40: NOMBRE | D40: IDEMPRESA
A41: 1 | B41: 123456 | C41: Lear MTO | D41: 310
A42: 1 | B42: 654312 | C42: Lear ELECTRICAL | D42: 311
A43: 1 | B43: 753159 | C43: Lear PMO | D43: 315
A44: 2 | B44: 951357 | C44: CAHPAT | D44: 531
A45: 2 | B45: 682715 | C45: FONDOS EMPLEADOS | D45: 710
G48: CASO1: SELECCIÓN MANUAL | J48: CASO2: SELECCIÓN GRUPO TODOS | L48: CASO3: MODIFICAR
A49: REL_GRUPO_ADMIN_ACCESO | G49: SELECCIONA GRUPO: | H49: <G-LEAR> | J49: SELECCIONA GRUPO: | K49: <G-LEAR> | L49: SELECCIONA GRUPO: | M49: <G-LEAR>
A50: IDGRUPO | B50: CONTRATO | C50: IDUSUARIOUNICO (ADMIN/VECTOR/SISTEMAS) | E50: ACTIVO
A51: 1 | B51: 0 | C51: 3e01db55-3f84-420f-aca5-031f07579b5b | E51: 1 | F51: () | G51: SELECCIONA SELECCIONAR TODOS LOS CONTRATOS | I51: (x) | J51: SELECCIONA SELECCIONAR TODOS LOS CONTRATOS | K51: (x) | L51: SELECCIONA SELECCIONAR TODOS LOS CONTRATOS
A52: 1 | B52: 0 | C52: 31312312-3f84-420f-aca5-031f07579b5b | E52: 1 | F52: (x) | G52: SELECCION MANUAL | I52: () | J52: SELECCION MANUAL | K52: () | L52: SELECCION MANUAL
A53: 1 | B53: 654312 | C53: dkasldjlasdkasñlkdña | E53: 1 | G53: 123456 | H53: X | J53: 123456 | L53: 123456
A54: 1 | B54: 753159 | C54: dkasldjlasdkasñlkdña | E54: 1 | G54: 654312 | J54: 654312 | L54: 654312
A55: 2 | B55: 682715 | C55: dkasldjlasdkasñlkdña | E55: 0 | G55: 753159 | H55: X | J55: 753159 | L55: 753159
A58: MOTIVO BLOQUEO
A59: 1 | B59: ABC
A60: 2 | B60: ABC
...

Sheet AUTH_COGNITO
B1: ADMIN: Activacion Aplicación Individual 1x1
A2: 1 | B2: Servicio para consultar participantes de una empresa, con los datos: idempresa, idpartipante, nombre, correo(blanco), ESTATUS(0)
A3: 1 | B3: Selecciona un participante, le captura un email y selecciona CONTINUAR
A4: 1.1 | B4: Se consume servicio para Activar pariticipante
A5: 2 | B5: Se verifica si el email no exista en PARTICIPANTE_AUTH, si no lo crea, genera IDUSUARIO_UNICO, se genera Codigo AC | H5: macastro@vector.com.mx | I5: 3e01db55-3f84-420f-aca5-031f07579b5b | J5: 912315
A6: 2.1 | B6: Se asocia el IDUSUARIO_UNICO a la idempresa-idparticipante
A7: 3 | B7: En la creacion o cambio de correo electronico, se envia correo de activacion al participante al correo que se registro
B9: ADMIN: Activacion Aplicación Masivo
A10: 1 | B10: El administrador tiene un XLS, con la relacion IDEMPRESA, IDPARTICIPANTE,email
A11: 2 | B11: El administrador importa el XLS y selecciona CONTINUAR
A12: 3 | B12: Pantalla de verificacion/conffirmacion, CONTINUAR
A13: 4 | B13: Se consume servicio para Activar pariticipantES
A14: 5 | B14: Se verifica por cada participante, que el email no exista en PARTICIPANTE_AUTH, si no lo crea, genera IDUSUARIO_UNICO, se genera Codigo AC | H14: macastro@vector.com.mx | I14: 3e01db55-3f84-420f-aca5-031f07579b5b | J14: 912315
A15: 5.1 | B15: Se asocia el IDUSUARIO_UNICO a la idempresa-idparticipante
A16: 6 | B16: En la creacion o cambio de correo electronico, se envia correo de activacion al participante al correo que se registro
B18: Registro Cognito
A19: 0 | B19: Captura: email, codigoactivacion, password, confirmacion password
A20: 1 | B20: Validar que el correo y idtokenunico que esta queriendo registrar exista en la BD participantes_auth
A21: 1.1 | B21: Si el correo a registrar no existe, presentar mensaje "El correo que intenta ingresa no se ecuentra registrado, contacta a tu administrador"
A22: 2 | B22: Se registra el correo en COGNITO, con sus credenciales ingresadas, se obtiene COGNITO-SUB y se registra en participantes_Auth
A23: 2.1 | B23: Registrar datos del dispositivo; generar identificador del dispositivo y almacenar en keychain
B25: Login
A26: 0 | B26: Captura: email, password, identificador dispositivo
A27: 1 | B27: COGNITO valida credenciales y nos entrega en JWT: Email, CONGNITO-SUB
A28: 1.1 | B28: Validar id dispositivo vs el registrado
A29: 2 | B29: Consume servicio de .NET para obtener relacion de empresas-partiipante, a partir del EMAIL-COGNITOSEC
B31: Resumen de contratos
A32: 1 | B32: Consumimos servicio AWS Resumen de contratos, se envia en HEADERS el JWT
A33: 2 | B33: Se entrega al front relacion de las empresas relacionadas en BD PARTICIPANTE | H33: {email, cognito-sec, empresas: [1-3050,1-3051,3-3551]} | J33: [{idorigen:1, idempresa:3051}, {idorigen:2, idempresa:3053}]
A34: 3 | B34: Se establece variable global en la app con el IDEMPRESA seleccionada
A35: 4 | B35: Se seleciona la 3051
B37: Consulta de Resumen de movimientos
A38: 1 | B38: Consumimos servicio AWS ejemplo Resumen Movimientos, se envia en HEADERS el JWT | H38: {autorization: barer | sesion:{2,3051,123456}}
A39: 1.1 | B39: /api/v1/movements? | H39: /api/v1/movements?
A40: =A38+1 -> 2 | B40: Se valida en AWS JWT vs COGNITO (LAMBDA)
A41: =A40+1 -> 3 | B41: Una vez autorizado por COGNITO, se consume servicio de .NET | H41: {
A42: 3.1 | B42: Cognito valida sesion valida (expiracion, vigencia, etc)?
A43: =A41+1 -> 4 | B43: AWS LAMBDA recibe por headers: JWT; | E43: se recibe tambien appversion, ip, geolocalizacion, osversion, ostype (andr/ios), canal (web/movil), phonemodel
A44: 4.1 | B44: AWS LAMBDA valida que no exista bloqueo de acceso a nivel global (dynamodb.DAHSBOARD_CONF_PARAMS)
A45: 4.2 | B45: AWS LAMBDA verficar version vigente app android/ios (dynamodb.DAHSBOARD_CONF_PARAMS)
...

Sheet PANTALLA DASHBOARD INI
B1: IDEMPRESA | C1: NOMBRE | D1: TIPO | E1: FECHA VALUACION | F1: NO.CONTRATO
B2: 351 | C2: CAHPAT | D2: Caja Ahorro | E2: 45772 | F2: 171365
B3: 213 | C3: FONDO EMPLEADOS | D3: Fondo | E3: 45772 | F3: 121312
B4: 513 | C4: Pensiones | D4: Pensiones | E4: 45772 | F4: 151613

Sheet BITACORA_TABLE
A1: FECHA | B1: HORA | C1: USUARIO | D1: PERFIL | E1: IDELEMENTO | F1: ELEMENTO | G1: IP | H1: GEO LAT | I1: GEO LON | J1: TIEMPO EJECUSION | K1: PARAMS | L1: ESTATUS PETICION
A2: 45776 | B2: 0.66666667 | C2: macastro@vector.com.mx | D2: SISTEMAS | E2: 10100 | F2: SERVICIO X | G2: 192.168.1.15 | H2: 12313213 | I2: 12313213 | J2: 3 | K2: abc | L2: 200
A3: 45776 | B3: 0.66666667 | C3: macastro@vector.com.mx | D3: SISTEMAS | E3: 10110 | F3: SERVICIO Y | G3: 192.168.1.15 | H3: 12313213 | I3: 12313213 | J3: 1 | K3: abc | L3: 200
A4: 45776 | B4: 0.66666667 | C4: macastro@vector.com.mx | D4: SISTEMAS | E4: 10400 | F4: SERVICIO Z | G4: 192.168.1.15 | H4: 12313213 | I4: 12313213 | J4: 4 | K4: abc | L4: 200

Sheet RECURSOS
A1: RECURSO | B1: TIPO | C1: ASIG | D1: DETALLE | E1: PROV
A2: BACKEND1 | B2: .NET | C2: ¿? | D2: IIS, SQLSERVER | E2: AXEN/NUEVO INTERNO
A3: BACKEND2 | B3: AWS | C3: ¿? | D3: API GATEWAY/LMABDA/COGNITO/RDS/DYNAMO | E3: ¿?
A4: FRONTEND1 | B4: REACT/REACT-NATIVE | C4: ¿? | D4: WEBDEVELOP | E4: ¿?

Sheet JIRA
A1: EPIC LINK | B1: SUMMARY | C1: Story Points
A2: RVPM-154 | B2: =_xlfn.CONCAT("[",ACTIVIDADES!A2,"] [",ACTIVIDADES!C2,"] ",ACTIVIDADES!I2," (",ACTIVIDADES!B2,")") -> [GENERAL] [BACK] Script para dar de alta SuperUsurio para Adminisitrar Adminsitradores (AWS) | C2: =ACTIVIDADES!K2 -> 8
A3: RVPM-154 | B3: =_xlfn.CONCAT("[",ACTIVIDADES!A3,"] [",ACTIVIDADES!C3,"] ",ACTIVIDADES!I3," (",ACTIVIDADES!B3,")") -> [GENERAL] [BACK] Script para generar estructuras de tablas nuevas de base de datos y carga inicial de datos y catalogos (AWS) | C3: =ACTIVIDADES!K3 -> 20
A4: RVPM-154 | B4: =_xlfn.CONCAT("[",ACTIVIDADES!A4,"] [",ACTIVIDADES!C4,"] ",ACTIVIDADES!I4," (",ACTIVIDADES!B4,")") -> [GENERAL] [BACK] Ruteo de peticiones REST a distintas base de datos dependiendo del Origen solicitado (.NET) | C4: =ACTIVIDADES!K4 -> 16
A5: RVPM-154 | B5: =_xlfn.CONCAT("[",ACTIVIDADES!A5,"] [",ACTIVIDADES!C5,"] ",ACTIVIDADES!I5," (",ACTIVIDADES!B5,")") -> [GENERAL] [BACK] Preparar nuevo PROYECTO para este set de servicios (AWS) | C5: =ACTIVIDADES!K5 -> 8
A6: RVPM-154 | B6: =_xlfn.CONCAT("[",ACTIVIDADES!A6,"] [",ACTIVIDADES!C6,"] ",ACTIVIDADES!I6," (",ACTIVIDADES!B6,")") -> [GENERAL] [BACK] Preparar ejemplo de servicio base GET/PUT/POST/DEL, con manejo de sesion JWT, validaciones y bitacora; para replicar en el universo de servicios (.NET) | C6: =ACTIVIDADES!K6 -> 16
A7: RVPM-154 | B7: =_xlfn.CONCAT("[",ACTIVIDADES!A7,"] [",ACTIVIDADES!C7,"] ",ACTIVIDADES!I7," (",ACTIVIDADES!B7,")") -> [GENERAL] [ARQ] Preparar proceso asincrono para generar archivo JSON de empresa SOLO para la empresa con bandera ACTIVOAPP true (JAVA) (.NET) | C7: =ACTIVIDADES!K7 -> 20
A8: RVPM-154 | B8: =_xlfn.CONCAT("[",ACTIVIDADES!A8,"] [",ACTIVIDADES!C8,"] ",ACTIVIDADES!I8," (",ACTIVIDADES!B8,")") -> [GENERAL] [BACK] Realizar envio de archivo JSON a bucket S3 AWS de empresas (.NET) | C8: =ACTIVIDADES!K8 -> 20
A9: RVPM-154 | B9: =_xlfn.CONCAT("[",ACTIVIDADES!A9,"] [",ACTIVIDADES!C9,"] ",ACTIVIDADES!I9," (",ACTIVIDADES!B9,")") -> [GENERAL] [BACK] Prepara CDK cdk-apisvector-pai: apigateway, lambdas, sqs, s3 (AWS) | C9: =ACTIVIDADES!K9 -> 8
A10: RVPM-154 | B10: =_xlfn.CONCAT("[",ACTIVIDADES!A10,"] [",ACTIVIDADES!C10,"] ",ACTIVIDADES!I10," (",ACTIVIDADES!B10,")") -> [GENERAL] [BACK] Prepara CDK cdk-apisvector-pai: estructuras de tablas dynamodb, json empresa; estatus proceso sqs, etc (AWS) | C10: =ACTIVIDADES!K10 -> 8
A11: RVPM-154 | B11: =_xlfn.CONCAT("[",ACTIVIDADES!A11,"] [",ACTIVIDADES!C11,"] ",ACTIVIDADES!I11," (",ACTIVIDADES!B11,")") -> [GENERAL] [BACK] Prepara CDK cdk-apisvector-pai: apigateway's domain vectorpai.api.vectordev.com.mx (AWS) | C11: =ACTIVIDADES!K11 -> 8
A12: RVPM-154 | B12: =_xlfn.CONCAT("[",ACTIVIDADES!A12,"] [",ACTIVIDADES!C12,"] ",ACTIVIDADES!I12," (",ACTIVIDADES!B12,")") -> [GENERAL] [BACK] Prepara CDK cdk-apisvector-pai: CID con workflow de git (Continuous integration deployment) (AWS) | C12: =ACTIVIDADES!K12 -> 16
A13: RVPM-154 | B13: =_xlfn.CONCAT("[",ACTIVIDADES!A13,"] [",ACTIVIDADES!C13,"] ",ACTIVIDADES!I13," (",ACTIVIDADES!B13,")") -> [GENERAL] [BACK] Configuracion de correos de codigo de activacion y codigo de confirmacion, templates (AWS) | C13: =ACTIVIDADES!K13 -> 16
... A156: RVPM-154 | B156: =_xlfn.CONCAT("[",ACTIVIDADES!A156,"] [",ACTIVIDADES!C156,"] ",ACTIVIDADES!I156," (",ACTIVIDADES!B156,")") -> [] [] () | C156: =ACTIVIDADES!K156 -> 0
